Workbook

Sheet CSE-M
A1: RAGHU ENGINEERING COLLEGE (A)
A2: Department of CSE
A3: 2024 AB CSE-M (REC) II B.Tech I Semester Attendance as on 11.06.2.205 onwards
A4: S.No | B4: Regd. No | C4: Name of the student | D4: Total | E4: Percentage
A5: Total classes taken till today | D5: =IFERROR(__xludf.DUMMYFUNCTION("IMPORTRANGE(""https://docs.google.com/spreadsheets/d/1pcI0H5_o88uChaoz3Jx8Lo2Z71zohG9q1pYbJLiJRZI/edit?gid=1086065120#gid=1086065120"", address(row($Z5),column($Z5),,,""CSE-M""))"),423.0) -> 423 | E5: %
A6: 1 | B6: 24981A05PS | C6: AMBALLA JASWANTH | D6: =IFERROR(__xludf.DUMMYFUNCTION("IMPORTRANGE(""https://docs.google.com/spreadsheets/d/1pcI0H5_o88uChaoz3Jx8Lo2Z71zohG9q1pYbJLiJRZI/edit?gid=1086065120#gid=1086065120"", address(row($Z6),column($Z6),,,""CSE-M""))"),279.0) -> 279 | E6: =ROUND(D6/$D$5*100,0) -> 66
A7: 2 | B7: 24981A05PT | C7: ANNAM SURYA CHANDRA TRINADH | D7: =IFERROR(__xludf.DUMMYFUNCTION("IMPORTRANGE(""https://docs.google.com/spreadsheets/d/1pcI0H5_o88uChaoz3Jx8Lo2Z71zohG9q1pYbJLiJRZI/edit?gid=1086065120#gid=1086065120"", address(row($Z7),column($Z7),,,""CSE-M""))"),273.0) -> 273 | E7: =ROUND(D7/$D$5*100,0) -> 65
A8: 3 | B8: 24981A05PU | C8: AYIREDDI SURYA ANUGJNA | D8: =IFERROR(__xludf.DUMMYFUNCTION("IMPORTRANGE(""https://docs.google.com/spreadsheets/d/1pcI0H5_o88uChaoz3Jx8Lo2Z71zohG9q1pYbJLiJRZI/edit?gid=1086065120#gid=1086065120"", address(row($Z8),column($Z8),,,""CSE-M""))"),393.0) -> 393 | E8: =ROUND(D8/$D$5*100,0) -> 93
A9: 4 | B9: 24981A05PV | C9: BAKI DURGA RAO | D9: =IFERROR(__xludf.DUMMYFUNCTION("IMPORTRANGE(""https://docs.google.com/spreadsheets/d/1pcI0H5_o88uChaoz3Jx8Lo2Z71zohG9q1pYbJLiJRZI/edit?gid=1086065120#gid=1086065120"", address(row($Z9),column($Z9),,,""CSE-M""))"),234.0) -> 234 | E9: =ROUND(D9/$D$5*100,0) -> 55
A10: 5 | B10: 24981A05PW | C10: BASAVA YAGNA SEKHAR | D10: =IFERROR(__xludf.DUMMYFUNCTION("IMPORTRANGE(""https://docs.google.com/spreadsheets/d/1pcI0H5_o88uChaoz3Jx8Lo2Z71zohG9q1pYbJLiJRZI/edit?gid=1086065120#gid=1086065120"", address(row($Z10),column($Z10),,,""CSE-M""))"),358.0) -> 358 | E10: =ROUND(D10/$D$5*100,0) -> 85
A11: 6 | B11: 24981A05PX | C11: BAVIRISETTI SAI | D11: =IFERROR(__xludf.DUMMYFUNCTION("IMPORTRANGE(""https://docs.google.com/spreadsheets/d/1pcI0H5_o88uChaoz3Jx8Lo2Z71zohG9q1pYbJLiJRZI/edit?gid=1086065120#gid=1086065120"", address(row($Z11),column($Z11),,,""CSE-M""))"),247.0) -> 247 | E11: =ROUND(D11/$D$5*100,0) -> 58
A12: 7 | B12: 24981A05PY | C12: BELLANA SIDDU | D12: =IFERROR(__xludf.DUMMYFUNCTION("IMPORTRANGE(""https://docs.google.com/spreadsheets/d/1pcI0H5_o88uChaoz3Jx8Lo2Z71zohG9q1pYbJLiJRZI/edit?gid=1086065120#gid=1086065120"", address(row($Z12),column($Z12),,,""CSE-M""))"),256.0) -> 256 | E12: =ROUND(D12/$D$5*100,0) -> 61
A13: 8 | B13: 24981A05PZ | C13: BHEEMIREDDI RAMANAMMA | D13: =IFERROR(__xludf.DUMMYFUNCTION("IMPORTRANGE(""https://docs.google.com/spreadsheets/d/1pcI0H5_o88uChaoz3Jx8Lo2Z71zohG9q1pYbJLiJRZI/edit?gid=1086065120#gid=1086065120"", address(row($Z13),column($Z13),,,""CSE-M""))"),339.0) -> 339 | E13: =ROUND(D13/$D$5*100,0) -> 80
A14: 9 | B14: 24981A05Q0 | C14: BODDETI YASWANTH | D14: =IFERROR(__xludf.DUMMYFUNCTION("IMPORTRANGE(""https://docs.google.com/spreadsheets/d/1pcI0H5_o88uChaoz3Jx8Lo2Z71zohG9q1pYbJLiJRZI/edit?gid=1086065120#gid=1086065120"", address(row($Z14),column($Z14),,,""CSE-M""))"),316.0) -> 316 | E14: =ROUND(D14/$D$5*100,0) -> 75
A15: 10 | B15: 24981A05Q1 | C15: BODDU SAI DEEPAK | D15: =IFERROR(__xludf.DUMMYFUNCTION("IMPORTRANGE(""https://docs.google.com/spreadsheets/d/1pcI0H5_o88uChaoz3Jx8Lo2Z71zohG9q1pYbJLiJRZI/edit?gid=1086065120#gid=1086065120"", address(row($Z15),column($Z15),,,""CSE-M""))"),214.0) -> 214 | E15: =ROUND(D15/$D$5*100,0) -> 51
A16: 11 | B16: 24981A05Q2 | C16: BONU MANASA | D16: =IFERROR(__xludf.DUMMYFUNCTION("IMPORTRANGE(""https://docs.google.com/spreadsheets/d/1pcI0H5_o88uChaoz3Jx8Lo2Z71zohG9q1pYbJLiJRZI/edit?gid=1086065120#gid=1086065120"", address(row($Z16),column($Z16),,,""CSE-M""))"),284.0) -> 284 | E16: =ROUND(D16/$D$5*100,0) -> 67
A17: 12 | B17: 24981A05Q3 | C17: BUGATHA SRUTHI | D17: =IFERROR(__xludf.DUMMYFUNCTION("IMPORTRANGE(""https://docs.google.com/spreadsheets/d/1pcI0H5_o88uChaoz3Jx8Lo2Z71zohG9q1pYbJLiJRZI/edit?gid=1086065120#gid=1086065120"", address(row($Z17),column($Z17),,,""CSE-M""))"),354.0) -> 354 | E17: =ROUND(D17/$D$5*100,0) -> 84
A18: 13 | B18: 24981A05Q4 | C18: BURLE DURGAPRASAD | D18: =IFERROR(__xludf.DUMMYFUNCTION("IMPORTRANGE(""https://docs.google.com/spreadsheets/d/1pcI0H5_o88uChaoz3Jx8Lo2Z71zohG9q1pYbJLiJRZI/edit?gid=1086065120#gid=1086065120"", address(row($Z18),column($Z18),,,""CSE-M""))"),320.0) -> 320 | E18: =ROUND(D18/$D$5*100,0) -> 76
A19: 14 | B19: 24981A05Q5 | C19: BYREDDI TEJASWINI | D19: =IFERROR(__xludf.DUMMYFUNCTION("IMPORTRANGE(""https://docs.google.com/spreadsheets/d/1pcI0H5_o88uChaoz3Jx8Lo2Z71zohG9q1pYbJLiJRZI/edit?gid=1086065120#gid=1086065120"", address(row($Z19),column($Z19),,,""CSE-M""))"),345.0) -> 345 | E19: =ROUND(D19/$D$5*100,0) -> 82
A20: 15 | B20: 24981A05Q6 | C20: CHELLANGI JYOTHI SWAROOP | D20: =IFERROR(__xludf.DUMMYFUNCTION("IMPORTRANGE(""https://docs.google.com/spreadsheets/d/1pcI0H5_o88uChaoz3Jx8Lo2Z71zohG9q1pYbJLiJRZI/edit?gid=1086065120#gid=1086065120"", address(row($Z20),column($Z20),,,""CSE-M""))"),292.0) -> 292 | E20: =ROUND(D20/$D$5*100,0) -> 69
A21: 16 | B21: 24981A05Q7 | C21: CHANDAKA SRINU | D21: =IFERROR(__xludf.DUMMYFUNCTION("IMPORTRANGE(""https://docs.google.com/spreadsheets/d/1pcI0H5_o88uChaoz3Jx8Lo2Z71zohG9q1pYbJLiJRZI/edit?gid=1086065120#gid=1086065120"", address(row($Z21),column($Z21),,,""CSE-M""))"),284.0) -> 284 | E21: =ROUND(D21/$D$5*100,0) -> 67
A22: 17 | B22: 24981A05Q8 | C22: CHEEPULLA LIKHITHA | D22: =IFERROR(__xludf.DUMMYFUNCTION("IMPORTRANGE(""https://docs.google.com/spreadsheets/d/1pcI0H5_o88uChaoz3Jx8Lo2Z71zohG9q1pYbJLiJRZI/edit?gid=1086065120#gid=1086065120"", address(row($Z22),column($Z22),,,""CSE-M""))"),304.0) -> 304 | E22: =ROUND(D22/$D$5*100,0) -> 72
A23: 18 | B23: 24981A05Q9 | C23: CHINTAPALLI JYOTHSNA | D23: =IFERROR(__xludf.DUMMYFUNCTION("IMPORTRANGE(""https://docs.google.com/spreadsheets/d/1pcI0H5_o88uChaoz3Jx8Lo2Z71zohG9q1pYbJLiJRZI/edit?gid=1086065120#gid=1086065120"", address(row($Z23),column($Z23),,,""CSE-M""))"),343.0) -> 343 | E23: =ROUND(D23/$D$5*100,0) -> 81
A24: 19 | B24: 24981A05QA | C24: CHINTAPALLI TULASI TANUJA | D24: =IFERROR(__xludf.DUMMYFUNCTION("IMPORTRANGE(""https://docs.google.com/spreadsheets/d/1pcI0H5_o88uChaoz3Jx8Lo2Z71zohG9q1pYbJLiJRZI/edit?gid=1086065120#gid=1086065120"", address(row($Z24),column($Z24),,,""CSE-M""))"),336.0) -> 336 | E24: =ROUND(D24/$D$5*100,0) -> 79
A25: 20 | B25: 24981A05QB | C25: CHITTELA VENKATA NIKHIL REDDY | D25: =IFERROR(__xludf.DUMMYFUNCTION("IMPORTRANGE(""https://docs.google.com/spreadsheets/d/1pcI0H5_o88uChaoz3Jx8Lo2Z71zohG9q1pYbJLiJRZI/edit?gid=1086065120#gid=1086065120"", address(row($Z25),column($Z25),,,""CSE-M""))"),413.0) -> 413 | E25: =ROUND(D25/$D$5*100,0) -> 98
A26: 21 | B26: 24981A05QC | C26: DAMALAPATI PADMAJA | D26: =IFERROR(__xludf.DUMMYFUNCTION("IMPORTRANGE(""https://docs.google.com/spreadsheets/d/1pcI0H5_o88uChaoz3Jx8Lo2Z71zohG9q1pYbJLiJRZI/edit?gid=1086065120#gid=1086065120"", address(row($Z26),column($Z26),,,""CSE-M""))"),364.0) -> 364 | E26: =ROUND(D26/$D$5*100,0) -> 86
A27: 22 | B27: 24981A05QD | C27: VANAMAREDDI NAVEENKUMAR REDDY | D27: =IFERROR(__xludf.DUMMYFUNCTION("IMPORTRANGE(""https://docs.google.com/spreadsheets/d/1pcI0H5_o88uChaoz3Jx8Lo2Z71zohG9q1pYbJLiJRZI/edit?gid=1086065120#gid=1086065120"", address(row($Z27),column($Z27),,,""CSE-M""))"),285.0) -> 285 | E27: =ROUND(D27/$D$5*100,0) -> 67
A28: 23 | B28: 24981A05QE | C28: DASARI VINAY KUMAR | D28: =IFERROR(__xludf.DUMMYFUNCTION("IMPORTRANGE(""https://docs.google.com/spreadsheets/d/1pcI0H5_o88uChaoz3Jx8Lo2Z71zohG9q1pYbJLiJRZI/edit?gid=1086065120#gid=1086065120"", address(row($Z28),column($Z28),,,""CSE-M""))"),347.0) -> 347 | E28: =ROUND(D28/$D$5*100,0) -> 82
A29: 24 | B29: 24981A05QF | C29: DEVARASETTY SAMIKSHA | D29: =IFERROR(__xludf.DUMMYFUNCTION("IMPORTRANGE(""https://docs.google.com/spreadsheets/d/1pcI0H5_o88uChaoz3Jx8Lo2Z71zohG9q1pYbJLiJRZI/edit?gid=1086065120#gid=1086065120"", address(row($Z29),column($Z29),,,""CSE-M""))"),352.0) -> 352 | E29: =ROUND(D29/$D$5*100,0) -> 83
A30: 25 | B30: 24981A05QG | C30: DOKI SAI CHARAN | D30: =IFERROR(__xludf.DUMMYFUNCTION("IMPORTRANGE(""https://docs.google.com/spreadsheets/d/1pcI0H5_o88uChaoz3Jx8Lo2Z71zohG9q1pYbJLiJRZI/edit?gid=1086065120#gid=1086065120"", address(row($Z30),column($Z30),,,""CSE-M""))"),363.0) -> 363 | E30: =ROUND(D30/$D$5*100,0) -> 86
A31: 26 | B31: 24981A05QH | C31: EATI AKANKSHA | D31: =IFERROR(__xludf.DUMMYFUNCTION("IMPORTRANGE(""https://docs.google.com/spreadsheets/d/1pcI0H5_o88uChaoz3Jx8Lo2Z71zohG9q1pYbJLiJRZI/edit?gid=1086065120#gid=1086065120"", address(row($Z31),column($Z31),,,""CSE-M""))"),315.0) -> 315 | E31: =ROUND(D31/$D$5*100,0) -> 74
A32: 27 | B32: 24981A05QI | C32: GADI THIRUMALA | D32: =IFERROR(__xludf.DUMMYFUNCTION("IMPORTRANGE(""https://docs.google.com/spreadsheets/d/1pcI0H5_o88uChaoz3Jx8Lo2Z71zohG9q1pYbJLiJRZI/edit?gid=1086065120#gid=1086065120"", address(row($Z32),column($Z32),,,""CSE-M""))"),315.0) -> 315 | E32: =ROUND(D32/$D$5*100,0) -> 74
A33: 28 | B33: 24981A05QJ | C33: GANDEM BHARATH | D33: =IFERROR(__xludf.DUMMYFUNCTION("IMPORTRANGE(""https://docs.google.com/spreadsheets/d/1pcI0H5_o88uChaoz3Jx8Lo2Z71zohG9q1pYbJLiJRZI/edit?gid=1086065120#gid=1086065120"", address(row($Z33),column($Z33),,,""CSE-M""))"),216.0) -> 216 | E33: =ROUND(D33/$D$5*100,0) -> 51
A34: 29 | B34: 24981A05QK | C34: GANGU DILLESWARA RAO | D34: =IFERROR(__xludf.DUMMYFUNCTION("IMPORTRANGE(""https://docs.google.com/spreadsheets/d/1pcI0H5_o88uChaoz3Jx8Lo2Z71zohG9q1pYbJLiJRZI/edit?gid=1086065120#gid=1086065120"", address(row($Z34),column($Z34),,,""CSE-M""))"),267.0) -> 267 | E34: =ROUND(D34/$D$5*100,0) -> 63
A35: 30 | B35: 24981A05QL | C35: GOTTAPU MOHAN KRISHNA | D35: =IFERROR(__xludf.DUMMYFUNCTION("IMPORTRANGE(""https://docs.google.com/spreadsheets/d/1pcI0H5_o88uChaoz3Jx8Lo2Z71zohG9q1pYbJLiJRZI/edit?gid=1086065120#gid=1086065120"", address(row($Z35),column($Z35),,,""CSE-M""))"),304.0) -> 304 | E35: =ROUND(D35/$D$5*100,0) -> 72
A36: 31 | B36: 24981A05QM | C36: JAMI SAHITHI | D36: =IFERROR(__xludf.DUMMYFUNCTION("IMPORTRANGE(""https://docs.google.com/spreadsheets/d/1pcI0H5_o88uChaoz3Jx8Lo2Z71zohG9q1pYbJLiJRZI/edit?gid=1086065120#gid=1086065120"", address(row($Z36),column($Z36),,,""CSE-M""))"),319.0) -> 319 | E36: =ROUND(D36/$D$5*100,0) -> 75
A37: 32 | B37: 24981A05QN | C37: JARUGULLA VISHNU VARDHAN | D37: =IFERROR(__xludf.DUMMYFUNCTION("IMPORTRANGE(""https://docs.google.com/spreadsheets/d/1pcI0H5_o88uChaoz3Jx8Lo2Z71zohG9q1pYbJLiJRZI/edit?gid=1086065120#gid=1086065120"", address(row($Z37),column($Z37),,,""CSE-M""))"),355.0) -> 355 | E37: =ROUND(D37/$D$5*100,0) -> 84
A38: 33 | B38: 24981A05QP | C38: KADAVALA JYOSHIKA | D38: =IFERROR(__xludf.DUMMYFUNCTION("IMPORTRANGE(""https://docs.google.com/spreadsheets/d/1pcI0H5_o88uChaoz3Jx8Lo2Z71zohG9q1pYbJLiJRZI/edit?gid=1086065120#gid=1086065120"", address(row($Z38),column($Z38),,,""CSE-M""))"),341.0) -> 341 | E38: =ROUND(D38/$D$5*100,0) -> 81
A39: 34 | B39: 24981A05QQ | C39: KARRI YUGANDHAR VINAYAKA NAGENDRA | D39: =IFERROR(__xludf.DUMMYFUNCTION("IMPORTRANGE(""https://docs.google.com/spreadsheets/d/1pcI0H5_o88uChaoz3Jx8Lo2Z71zohG9q1pYbJLiJRZI/edit?gid=1086065120#gid=1086065120"", address(row($Z39),column($Z39),,,""CSE-M""))"),296.0) -> 296 | E39: =ROUND(D39/$D$5*100,0) -> 70
A40: 35 | B40: 24981A05QR | C40: KAVALI MADHAVA BHUVANESWAR | D40: =IFERROR(__xludf.DUMMYFUNCTION("IMPORTRANGE(""https://docs.google.com/spreadsheets/d/1pcI0H5_o88uChaoz3Jx8Lo2Z71zohG9q1pYbJLiJRZI/edit?gid=1086065120#gid=1086065120"", address(row($Z40),column($Z40),,,""CSE-M""))"),290.0) -> 290 | E40: =ROUND(D40/$D$5*100,0) -> 69
...

Sheet CSE-N
A1: RAGHU ENGINEERING COLLEGE (A)
A2: Department of CSE
A3: 2024 AB CSE-N (REC) II B.Tech I Semester Attendance as on 11.06.2025 onwards
A4: S.No | B4: Regd. No | C4: Name of the student | D4: Total | E4: Percentage
A5: Total classes taken till today | D5: =IFERROR(__xludf.DUMMYFUNCTION("IMPORTRANGE(""https://docs.google.com/spreadsheets/d/1pcI0H5_o88uChaoz3Jx8Lo2Z71zohG9q1pYbJLiJRZI/edit?gid=2034297422#gid=2034297422"", address(row($Z5),column($Z5),,,""CSE-N""))"),413.0) -> 413 | E5: %
A6: 1 | B6: 24981A05RV | C6: BIDDIKA AJAY | D6: =IFERROR(__xludf.DUMMYFUNCTION("IMPORTRANGE(""https://docs.google.com/spreadsheets/d/1pcI0H5_o88uChaoz3Jx8Lo2Z71zohG9q1pYbJLiJRZI/edit?gid=2034297422#gid=2034297422"", address(row($Z6),column($Z6),,,""CSE-N""))"),82.0) -> 82 | E6: =ROUND(D6/$D$5*100,0) -> 20
A7: 2 | B7: 24981A05RW | C7: BONGI RUCHITHA | D7: =IFERROR(__xludf.DUMMYFUNCTION("IMPORTRANGE(""https://docs.google.com/spreadsheets/d/1pcI0H5_o88uChaoz3Jx8Lo2Z71zohG9q1pYbJLiJRZI/edit?gid=2034297422#gid=2034297422"", address(row($Z7),column($Z7),,,""CSE-N""))"),372.0) -> 372 | E7: =ROUND(D7/$D$5*100,0) -> 90
A8: 3 | B8: 24981A05RX | C8: CHINAPANA AJAY | D8: =IFERROR(__xludf.DUMMYFUNCTION("IMPORTRANGE(""https://docs.google.com/spreadsheets/d/1pcI0H5_o88uChaoz3Jx8Lo2Z71zohG9q1pYbJLiJRZI/edit?gid=2034297422#gid=2034297422"", address(row($Z8),column($Z8),,,""CSE-N""))"),383.0) -> 383 | E8: =ROUND(D8/$D$5*100,0) -> 93
A9: 4 | B9: 24981A05RY | C9: CHINTA JAHNAVI | D9: =IFERROR(__xludf.DUMMYFUNCTION("IMPORTRANGE(""https://docs.google.com/spreadsheets/d/1pcI0H5_o88uChaoz3Jx8Lo2Z71zohG9q1pYbJLiJRZI/edit?gid=2034297422#gid=2034297422"", address(row($Z9),column($Z9),,,""CSE-N""))"),274.0) -> 274 | E9: =ROUND(D9/$D$5*100,0) -> 66
A10: 5 | B10: 24981A05RZ | C10: CHIRRA SANTHOSH REDDY | D10: =IFERROR(__xludf.DUMMYFUNCTION("IMPORTRANGE(""https://docs.google.com/spreadsheets/d/1pcI0H5_o88uChaoz3Jx8Lo2Z71zohG9q1pYbJLiJRZI/edit?gid=2034297422#gid=2034297422"", address(row($Z10),column($Z10),,,""CSE-N""))"),209.0) -> 209 | E10: =ROUND(D10/$D$5*100,0) -> 51
A11: 6 | B11: 24981A05S0 | C11: DARLA PRAVEEN KUMAR | D11: =IFERROR(__xludf.DUMMYFUNCTION("IMPORTRANGE(""https://docs.google.com/spreadsheets/d/1pcI0H5_o88uChaoz3Jx8Lo2Z71zohG9q1pYbJLiJRZI/edit?gid=2034297422#gid=2034297422"", address(row($Z11),column($Z11),,,""CSE-N""))"),291.0) -> 291 | E11: =ROUND(D11/$D$5*100,0) -> 70
A12: 7 | B12: 24981A05S1 | C12: DEVARAPALLI GLORY JASIKA | D12: =IFERROR(__xludf.DUMMYFUNCTION("IMPORTRANGE(""https://docs.google.com/spreadsheets/d/1pcI0H5_o88uChaoz3Jx8Lo2Z71zohG9q1pYbJLiJRZI/edit?gid=2034297422#gid=2034297422"", address(row($Z12),column($Z12),,,""CSE-N""))"),197.0) -> 197 | E12: =ROUND(D12/$D$5*100,0) -> 48
A13: 8 | B13: 24981A05S2 | C13: DOPPALA GOUTHAM | D13: =IFERROR(__xludf.DUMMYFUNCTION("IMPORTRANGE(""https://docs.google.com/spreadsheets/d/1pcI0H5_o88uChaoz3Jx8Lo2Z71zohG9q1pYbJLiJRZI/edit?gid=2034297422#gid=2034297422"", address(row($Z13),column($Z13),,,""CSE-N""))"),227.0) -> 227 | E13: =ROUND(D13/$D$5*100,0) -> 55
A14: 9 | B14: 24981A05S3 | C14: DURISETI USHA ABHINAYA | D14: =IFERROR(__xludf.DUMMYFUNCTION("IMPORTRANGE(""https://docs.google.com/spreadsheets/d/1pcI0H5_o88uChaoz3Jx8Lo2Z71zohG9q1pYbJLiJRZI/edit?gid=2034297422#gid=2034297422"", address(row($Z14),column($Z14),,,""CSE-N""))"),327.0) -> 327 | E14: =ROUND(D14/$D$5*100,0) -> 79
A15: 10 | B15: 24981A05S4 | C15: GODA KAUSHIK | D15: =IFERROR(__xludf.DUMMYFUNCTION("IMPORTRANGE(""https://docs.google.com/spreadsheets/d/1pcI0H5_o88uChaoz3Jx8Lo2Z71zohG9q1pYbJLiJRZI/edit?gid=2034297422#gid=2034297422"", address(row($Z15),column($Z15),,,""CSE-N""))"),216.0) -> 216 | E15: =ROUND(D15/$D$5*100,0) -> 52
A16: 11 | B16: 24981A05S5 | C16: GOLLAPALLI ARAVIND | D16: =IFERROR(__xludf.DUMMYFUNCTION("IMPORTRANGE(""https://docs.google.com/spreadsheets/d/1pcI0H5_o88uChaoz3Jx8Lo2Z71zohG9q1pYbJLiJRZI/edit?gid=2034297422#gid=2034297422"", address(row($Z16),column($Z16),,,""CSE-N""))"),181.0) -> 181 | E16: =ROUND(D16/$D$5*100,0) -> 44
A17: 12 | B17: 24981A05S6 | C17: GOLLAPALLI MAHENDRA | D17: =IFERROR(__xludf.DUMMYFUNCTION("IMPORTRANGE(""https://docs.google.com/spreadsheets/d/1pcI0H5_o88uChaoz3Jx8Lo2Z71zohG9q1pYbJLiJRZI/edit?gid=2034297422#gid=2034297422"", address(row($Z17),column($Z17),,,""CSE-N""))"),284.0) -> 284 | E17: =ROUND(D17/$D$5*100,0) -> 69
A18: 13 | B18: 24981A05S7 | C18: GORLE PARAMESH KUMAR | D18: =IFERROR(__xludf.DUMMYFUNCTION("IMPORTRANGE(""https://docs.google.com/spreadsheets/d/1pcI0H5_o88uChaoz3Jx8Lo2Z71zohG9q1pYbJLiJRZI/edit?gid=2034297422#gid=2034297422"", address(row($Z18),column($Z18),,,""CSE-N""))"),240.0) -> 240 | E18: =ROUND(D18/$D$5*100,0) -> 58
A19: 14 | B19: 24981A05S8 | C19: GORUSETTI NITHIN | D19: =IFERROR(__xludf.DUMMYFUNCTION("IMPORTRANGE(""https://docs.google.com/spreadsheets/d/1pcI0H5_o88uChaoz3Jx8Lo2Z71zohG9q1pYbJLiJRZI/edit?gid=2034297422#gid=2034297422"", address(row($Z19),column($Z19),,,""CSE-N""))"),346.0) -> 346 | E19: =ROUND(D19/$D$5*100,0) -> 84
A20: 15 | B20: 24981A05S9 | C20: GOWRIPATTAPU HARSHAVARDHAN | D20: =IFERROR(__xludf.DUMMYFUNCTION("IMPORTRANGE(""https://docs.google.com/spreadsheets/d/1pcI0H5_o88uChaoz3Jx8Lo2Z71zohG9q1pYbJLiJRZI/edit?gid=2034297422#gid=2034297422"", address(row($Z20),column($Z20),,,""CSE-N""))"),252.0) -> 252 | E20: =ROUND(D20/$D$5*100,0) -> 61
A21: 16 | B21: 24981A05SA | C21: GUNTHA RAHUL | D21: =IFERROR(__xludf.DUMMYFUNCTION("IMPORTRANGE(""https://docs.google.com/spreadsheets/d/1pcI0H5_o88uChaoz3Jx8Lo2Z71zohG9q1pYbJLiJRZI/edit?gid=2034297422#gid=2034297422"", address(row($Z21),column($Z21),,,""CSE-N""))"),335.0) -> 335 | E21: =ROUND(D21/$D$5*100,0) -> 81
A22: 17 | B22: 24981A05SB | C22: GURUNADHAM MANOHAR | D22: =IFERROR(__xludf.DUMMYFUNCTION("IMPORTRANGE(""https://docs.google.com/spreadsheets/d/1pcI0H5_o88uChaoz3Jx8Lo2Z71zohG9q1pYbJLiJRZI/edit?gid=2034297422#gid=2034297422"", address(row($Z22),column($Z22),,,""CSE-N""))"),147.0) -> 147 | E22: =ROUND(D22/$D$5*100,0) -> 36
A23: 18 | B23: 24981A05SC | C23: INJETI PRIYADARSHINI | D23: =IFERROR(__xludf.DUMMYFUNCTION("IMPORTRANGE(""https://docs.google.com/spreadsheets/d/1pcI0H5_o88uChaoz3Jx8Lo2Z71zohG9q1pYbJLiJRZI/edit?gid=2034297422#gid=2034297422"", address(row($Z23),column($Z23),,,""CSE-N""))"),260.0) -> 260 | E23: =ROUND(D23/$D$5*100,0) -> 63
A24: 19 | B24: 24981A05SD | C24: IPPILI HASINI | D24: =IFERROR(__xludf.DUMMYFUNCTION("IMPORTRANGE(""https://docs.google.com/spreadsheets/d/1pcI0H5_o88uChaoz3Jx8Lo2Z71zohG9q1pYbJLiJRZI/edit?gid=2034297422#gid=2034297422"", address(row($Z24),column($Z24),,,""CSE-N""))"),287.0) -> 287 | E24: =ROUND(D24/$D$5*100,0) -> 69
A25: 20 | B25: 24981A05SE | C25: JALIYA VIVEK | D25: =IFERROR(__xludf.DUMMYFUNCTION("IMPORTRANGE(""https://docs.google.com/spreadsheets/d/1pcI0H5_o88uChaoz3Jx8Lo2Z71zohG9q1pYbJLiJRZI/edit?gid=2034297422#gid=2034297422"", address(row($Z25),column($Z25),,,""CSE-N""))"),203.0) -> 203 | E25: =ROUND(D25/$D$5*100,0) -> 49
A26: 21 | B26: 24981A05SF | C26: JAMANA GURU CHARAN TEJA | D26: =IFERROR(__xludf.DUMMYFUNCTION("IMPORTRANGE(""https://docs.google.com/spreadsheets/d/1pcI0H5_o88uChaoz3Jx8Lo2Z71zohG9q1pYbJLiJRZI/edit?gid=2034297422#gid=2034297422"", address(row($Z26),column($Z26),,,""CSE-N""))"),241.0) -> 241 | E26: =ROUND(D26/$D$5*100,0) -> 58
A27: 22 | B27: 24981A05SG | C27: KAKARA HEMANTH KAKODHKAR | D27: =IFERROR(__xludf.DUMMYFUNCTION("IMPORTRANGE(""https://docs.google.com/spreadsheets/d/1pcI0H5_o88uChaoz3Jx8Lo2Z71zohG9q1pYbJLiJRZI/edit?gid=2034297422#gid=2034297422"", address(row($Z27),column($Z27),,,""CSE-N""))"),239.0) -> 239 | E27: =ROUND(D27/$D$5*100,0) -> 58
A28: 23 | B28: 24981A05SH | C28: KAMMINANA MANASA | D28: =IFERROR(__xludf.DUMMYFUNCTION("IMPORTRANGE(""https://docs.google.com/spreadsheets/d/1pcI0H5_o88uChaoz3Jx8Lo2Z71zohG9q1pYbJLiJRZI/edit?gid=2034297422#gid=2034297422"", address(row($Z28),column($Z28),,,""CSE-N""))"),316.0) -> 316 | E28: =ROUND(D28/$D$5*100,0) -> 77
A29: 24 | B29: 24981A05SI | C29: KARUPATI ASIRVADAM | D29: =IFERROR(__xludf.DUMMYFUNCTION("IMPORTRANGE(""https://docs.google.com/spreadsheets/d/1pcI0H5_o88uChaoz3Jx8Lo2Z71zohG9q1pYbJLiJRZI/edit?gid=2034297422#gid=2034297422"", address(row($Z29),column($Z29),,,""CSE-N""))"),262.0) -> 262 | E29: =ROUND(D29/$D$5*100,0) -> 63
A30: 25 | B30: 24981A05SJ | C30: KASARLA CHARANKUMAR | D30: =IFERROR(__xludf.DUMMYFUNCTION("IMPORTRANGE(""https://docs.google.com/spreadsheets/d/1pcI0H5_o88uChaoz3Jx8Lo2Z71zohG9q1pYbJLiJRZI/edit?gid=2034297422#gid=2034297422"", address(row($Z30),column($Z30),,,""CSE-N""))"),292.0) -> 292 | E30: =ROUND(D30/$D$5*100,0) -> 71
A31: 26 | B31: 24981A05SK | C31: KATTA ACHYUTH KUMAR | D31: =IFERROR(__xludf.DUMMYFUNCTION("IMPORTRANGE(""https://docs.google.com/spreadsheets/d/1pcI0H5_o88uChaoz3Jx8Lo2Z71zohG9q1pYbJLiJRZI/edit?gid=2034297422#gid=2034297422"", address(row($Z31),column($Z31),,,""CSE-N""))"),253.0) -> 253 | E31: =ROUND(D31/$D$5*100,0) -> 61
A32: 27 | B32: 24981A05SL | C32: KOLLI KARTHIK | D32: =IFERROR(__xludf.DUMMYFUNCTION("IMPORTRANGE(""https://docs.google.com/spreadsheets/d/1pcI0H5_o88uChaoz3Jx8Lo2Z71zohG9q1pYbJLiJRZI/edit?gid=2034297422#gid=2034297422"", address(row($Z32),column($Z32),,,""CSE-N""))"),192.0) -> 192 | E32: =ROUND(D32/$D$5*100,0) -> 46
A33: 28 | B33: 24981A05SM | C33: KONDALA VASANTHA KUMAR | D33: =IFERROR(__xludf.DUMMYFUNCTION("IMPORTRANGE(""https://docs.google.com/spreadsheets/d/1pcI0H5_o88uChaoz3Jx8Lo2Z71zohG9q1pYbJLiJRZI/edit?gid=2034297422#gid=2034297422"", address(row($Z33),column($Z33),,,""CSE-N""))"),279.0) -> 279 | E33: =ROUND(D33/$D$5*100,0) -> 68
A34: 29 | B34: 24981A05SN | C34: KONNI LOKESH | D34: =IFERROR(__xludf.DUMMYFUNCTION("IMPORTRANGE(""https://docs.google.com/spreadsheets/d/1pcI0H5_o88uChaoz3Jx8Lo2Z71zohG9q1pYbJLiJRZI/edit?gid=2034297422#gid=2034297422"", address(row($Z34),column($Z34),,,""CSE-N""))"),373.0) -> 373 | E34: =ROUND(D34/$D$5*100,0) -> 90
A35: 30 | B35: 24981A05SP | C35: KOPPISETTI SATYA VENKATA SURYA DURGAPRASAD | D35: =IFERROR(__xludf.DUMMYFUNCTION("IMPORTRANGE(""https://docs.google.com/spreadsheets/d/1pcI0H5_o88uChaoz3Jx8Lo2Z71zohG9q1pYbJLiJRZI/edit?gid=2034297422#gid=2034297422"", address(row($Z35),column($Z35),,,""CSE-N""))"),340.0) -> 340 | E35: =ROUND(D35/$D$5*100,0) -> 82
A36: 31 | B36: 24981A05SQ | C36: KORRA CHANDANA | D36: =IFERROR(__xludf.DUMMYFUNCTION("IMPORTRANGE(""https://docs.google.com/spreadsheets/d/1pcI0H5_o88uChaoz3Jx8Lo2Z71zohG9q1pYbJLiJRZI/edit?gid=2034297422#gid=2034297422"", address(row($Z36),column($Z36),,,""CSE-N""))"),266.0) -> 266 | E36: =ROUND(D36/$D$5*100,0) -> 64
A37: 32 | B37: 24981A05SR | C37: KUKKALA ANAND | D37: =IFERROR(__xludf.DUMMYFUNCTION("IMPORTRANGE(""https://docs.google.com/spreadsheets/d/1pcI0H5_o88uChaoz3Jx8Lo2Z71zohG9q1pYbJLiJRZI/edit?gid=2034297422#gid=2034297422"", address(row($Z37),column($Z37),,,""CSE-N""))"),376.0) -> 376 | E37: =ROUND(D37/$D$5*100,0) -> 91
A38: 33 | B38: 24981A05SS | C38: LAKKIMSETTI LOHITH KUMARA SWAMY | D38: =IFERROR(__xludf.DUMMYFUNCTION("IMPORTRANGE(""https://docs.google.com/spreadsheets/d/1pcI0H5_o88uChaoz3Jx8Lo2Z71zohG9q1pYbJLiJRZI/edit?gid=2034297422#gid=2034297422"", address(row($Z38),column($Z38),,,""CSE-N""))"),251.0) -> 251 | E38: =ROUND(D38/$D$5*100,0) -> 61
A39: 34 | B39: 24981A05ST | C39: LOTLA SRI SATYA NAVADEEP | D39: =IFERROR(__xludf.DUMMYFUNCTION("IMPORTRANGE(""https://docs.google.com/spreadsheets/d/1pcI0H5_o88uChaoz3Jx8Lo2Z71zohG9q1pYbJLiJRZI/edit?gid=2034297422#gid=2034297422"", address(row($Z39),column($Z39),,,""CSE-N""))"),324.0) -> 324 | E39: =ROUND(D39/$D$5*100,0) -> 78
A40: 35 | B40: 24981A05SU | C40: MANIKANETULA MOUNIKA | D40: =IFERROR(__xludf.DUMMYFUNCTION("IMPORTRANGE(""https://docs.google.com/spreadsheets/d/1pcI0H5_o88uChaoz3Jx8Lo2Z71zohG9q1pYbJLiJRZI/edit?gid=2034297422#gid=2034297422"", address(row($Z40),column($Z40),,,""CSE-N""))"),349.0) -> 349 | E40: =ROUND(D40/$D$5*100,0) -> 85
...

Sheet CSE-O
A1: RAGHU ENGINEERING COLLEGE (A)
A2: Department of CSE
A3: 2024 AB CSE-O(REC) II B.Tech I Semester Attendance as on 11.06.2025 onwards
A4: S.No | B4: Regd. No | C4: Name of the student | D4: Total | E4: Percentage
A5: Total classes taken till today | D5: =IFERROR(__xludf.DUMMYFUNCTION("IMPORTRANGE(""https://docs.google.com/spreadsheets/d/1pcI0H5_o88uChaoz3Jx8Lo2Z71zohG9q1pYbJLiJRZI/edit?gid=760579392#gid=760579392"", address(row($Z5),column($Z5),,,""CSE-O""))"),421.0) -> 421 | E5: %
A6: 1 | B6: 24981A05TS | C6: VANDANA THANU SRI | D6: =IFERROR(__xludf.DUMMYFUNCTION("IMPORTRANGE(""https://docs.google.com/spreadsheets/d/1pcI0H5_o88uChaoz3Jx8Lo2Z71zohG9q1pYbJLiJRZI/edit?gid=760579392#gid=760579392"", address(row($Z6),column($Z6),,,""CSE-O""))"),244.0) -> 244 | E6: =ROUND(D6/$D$5*100,0) -> 58
A7: 2 | B7: 24981A05TT | C7: BAKI SAI SRUJANA | D7: =IFERROR(__xludf.DUMMYFUNCTION("IMPORTRANGE(""https://docs.google.com/spreadsheets/d/1pcI0H5_o88uChaoz3Jx8Lo2Z71zohG9q1pYbJLiJRZI/edit?gid=760579392#gid=760579392"", address(row($Z7),column($Z7),,,""CSE-O""))"),387.0) -> 387 | E7: =ROUND(D7/$D$5*100,0) -> 92
A8: 3 | B8: 24981A05TU | C8: BOGADI VENI CHANDRIKA | D8: =IFERROR(__xludf.DUMMYFUNCTION("IMPORTRANGE(""https://docs.google.com/spreadsheets/d/1pcI0H5_o88uChaoz3Jx8Lo2Z71zohG9q1pYbJLiJRZI/edit?gid=760579392#gid=760579392"", address(row($Z8),column($Z8),,,""CSE-O""))"),388.0) -> 388 | E8: =ROUND(D8/$D$5*100,0) -> 92
A9: 4 | B9: 24981A05TV | C9: BOJJA VINEEL | D9: =IFERROR(__xludf.DUMMYFUNCTION("IMPORTRANGE(""https://docs.google.com/spreadsheets/d/1pcI0H5_o88uChaoz3Jx8Lo2Z71zohG9q1pYbJLiJRZI/edit?gid=760579392#gid=760579392"", address(row($Z9),column($Z9),,,""CSE-O""))"),170.0) -> 170 | E9: =ROUND(D9/$D$5*100,0) -> 40
A10: 5 | B10: 24981A05TW | C10: BOOSA LOKESWARI | D10: =IFERROR(__xludf.DUMMYFUNCTION("IMPORTRANGE(""https://docs.google.com/spreadsheets/d/1pcI0H5_o88uChaoz3Jx8Lo2Z71zohG9q1pYbJLiJRZI/edit?gid=760579392#gid=760579392"", address(row($Z10),column($Z10),,,""CSE-O""))"),234.0) -> 234 | E10: =ROUND(D10/$D$5*100,0) -> 56
A11: 6 | B11: 24981A05TX | C11: CHUKKA RESHMA | D11: =IFERROR(__xludf.DUMMYFUNCTION("IMPORTRANGE(""https://docs.google.com/spreadsheets/d/1pcI0H5_o88uChaoz3Jx8Lo2Z71zohG9q1pYbJLiJRZI/edit?gid=760579392#gid=760579392"", address(row($Z11),column($Z11),,,""CSE-O""))"),359.0) -> 359 | E11: =ROUND(D11/$D$5*100,0) -> 85
A12: 7 | B12: 24981A05TY | C12: DAGGUPATI KARTHIK | D12: =IFERROR(__xludf.DUMMYFUNCTION("IMPORTRANGE(""https://docs.google.com/spreadsheets/d/1pcI0H5_o88uChaoz3Jx8Lo2Z71zohG9q1pYbJLiJRZI/edit?gid=760579392#gid=760579392"", address(row($Z12),column($Z12),,,""CSE-O""))"),360.0) -> 360 | E12: =ROUND(D12/$D$5*100,0) -> 86
A13: 8 | B13: 24981A05TZ | C13: DAMARASINGI LAHARI | D13: =IFERROR(__xludf.DUMMYFUNCTION("IMPORTRANGE(""https://docs.google.com/spreadsheets/d/1pcI0H5_o88uChaoz3Jx8Lo2Z71zohG9q1pYbJLiJRZI/edit?gid=760579392#gid=760579392"", address(row($Z13),column($Z13),,,""CSE-O""))"),293.0) -> 293 | E13: =ROUND(D13/$D$5*100,0) -> 70
A14: 9 | B14: 24981A05U0 | C14: DONAKA HEPSIBHA | D14: =IFERROR(__xludf.DUMMYFUNCTION("IMPORTRANGE(""https://docs.google.com/spreadsheets/d/1pcI0H5_o88uChaoz3Jx8Lo2Z71zohG9q1pYbJLiJRZI/edit?gid=760579392#gid=760579392"", address(row($Z14),column($Z14),,,""CSE-O""))"),292.0) -> 292 | E14: =ROUND(D14/$D$5*100,0) -> 69
A15: 10 | B15: 24981A05U1 | C15: DOWLAPALLI YOGESH | D15: =IFERROR(__xludf.DUMMYFUNCTION("IMPORTRANGE(""https://docs.google.com/spreadsheets/d/1pcI0H5_o88uChaoz3Jx8Lo2Z71zohG9q1pYbJLiJRZI/edit?gid=760579392#gid=760579392"", address(row($Z15),column($Z15),,,""CSE-O""))"),297.0) -> 297 | E15: =ROUND(D15/$D$5*100,0) -> 71
A16: 11 | B16: 24981A05U2 | C16: DURGAM NEHAL NIHARIKA | D16: =IFERROR(__xludf.DUMMYFUNCTION("IMPORTRANGE(""https://docs.google.com/spreadsheets/d/1pcI0H5_o88uChaoz3Jx8Lo2Z71zohG9q1pYbJLiJRZI/edit?gid=760579392#gid=760579392"", address(row($Z16),column($Z16),,,""CSE-O""))"),0.0) -> 0 | E16: =ROUND(D16/$D$5*100,0) -> 0
A17: 12 | B17: 24981A05U3 | C17: EMANDI BHUVAN VENKATA SAI | D17: =IFERROR(__xludf.DUMMYFUNCTION("IMPORTRANGE(""https://docs.google.com/spreadsheets/d/1pcI0H5_o88uChaoz3Jx8Lo2Z71zohG9q1pYbJLiJRZI/edit?gid=760579392#gid=760579392"", address(row($Z17),column($Z17),,,""CSE-O""))"),326.0) -> 326 | E17: =ROUND(D17/$D$5*100,0) -> 77
A18: 13 | B18: 24981A05U5 | C18: GANDEPALLI JAYAPRAKASH | D18: =IFERROR(__xludf.DUMMYFUNCTION("IMPORTRANGE(""https://docs.google.com/spreadsheets/d/1pcI0H5_o88uChaoz3Jx8Lo2Z71zohG9q1pYbJLiJRZI/edit?gid=760579392#gid=760579392"", address(row($Z18),column($Z18),,,""CSE-O""))"),310.0) -> 310 | E18: =ROUND(D18/$D$5*100,0) -> 74
A19: 14 | B19: 24981A05U6 | C19: GINNI MOHAN SAI KUMAR REDDY | D19: =IFERROR(__xludf.DUMMYFUNCTION("IMPORTRANGE(""https://docs.google.com/spreadsheets/d/1pcI0H5_o88uChaoz3Jx8Lo2Z71zohG9q1pYbJLiJRZI/edit?gid=760579392#gid=760579392"", address(row($Z19),column($Z19),,,""CSE-O""))"),335.0) -> 335 | E19: =ROUND(D19/$D$5*100,0) -> 80
A20: 15 | B20: 24981A05U7 | C20: GUDIVADA KRISHNAVENI | D20: =IFERROR(__xludf.DUMMYFUNCTION("IMPORTRANGE(""https://docs.google.com/spreadsheets/d/1pcI0H5_o88uChaoz3Jx8Lo2Z71zohG9q1pYbJLiJRZI/edit?gid=760579392#gid=760579392"", address(row($Z20),column($Z20),,,""CSE-O""))"),388.0) -> 388 | E20: =ROUND(D20/$D$5*100,0) -> 92
A21: 16 | B21: 24981A05U8 | C21: GUJJELA DEVI | D21: =IFERROR(__xludf.DUMMYFUNCTION("IMPORTRANGE(""https://docs.google.com/spreadsheets/d/1pcI0H5_o88uChaoz3Jx8Lo2Z71zohG9q1pYbJLiJRZI/edit?gid=760579392#gid=760579392"", address(row($Z21),column($Z21),,,""CSE-O""))"),358.0) -> 358 | E21: =ROUND(D21/$D$5*100,0) -> 85
A22: 17 | B22: 24981A05U9 | C22: ILLURI ANAND BABU | D22: =IFERROR(__xludf.DUMMYFUNCTION("IMPORTRANGE(""https://docs.google.com/spreadsheets/d/1pcI0H5_o88uChaoz3Jx8Lo2Z71zohG9q1pYbJLiJRZI/edit?gid=760579392#gid=760579392"", address(row($Z22),column($Z22),,,""CSE-O""))"),167.0) -> 167 | E22: =ROUND(D22/$D$5*100,0) -> 40
A23: 18 | B23: 24981A05UA | C23: JEERU DHEERAJ REDDY | D23: =IFERROR(__xludf.DUMMYFUNCTION("IMPORTRANGE(""https://docs.google.com/spreadsheets/d/1pcI0H5_o88uChaoz3Jx8Lo2Z71zohG9q1pYbJLiJRZI/edit?gid=760579392#gid=760579392"", address(row($Z23),column($Z23),,,""CSE-O""))"),152.0) -> 152 | E23: =ROUND(D23/$D$5*100,0) -> 36
A24: 19 | B24: 24981A05UB | C24: JALUMURI TULASI | D24: =IFERROR(__xludf.DUMMYFUNCTION("IMPORTRANGE(""https://docs.google.com/spreadsheets/d/1pcI0H5_o88uChaoz3Jx8Lo2Z71zohG9q1pYbJLiJRZI/edit?gid=760579392#gid=760579392"", address(row($Z24),column($Z24),,,""CSE-O""))"),295.0) -> 295 | E24: =ROUND(D24/$D$5*100,0) -> 70
A25: 20 | B25: 24981A05UC | C25: JOSHUA ANTHONY SUDHAKAR | D25: =IFERROR(__xludf.DUMMYFUNCTION("IMPORTRANGE(""https://docs.google.com/spreadsheets/d/1pcI0H5_o88uChaoz3Jx8Lo2Z71zohG9q1pYbJLiJRZI/edit?gid=760579392#gid=760579392"", address(row($Z25),column($Z25),,,""CSE-O""))"),337.0) -> 337 | E25: =ROUND(D25/$D$5*100,0) -> 80
A26: 21 | B26: 24981A05UD | C26: KOMMANAMANCHI SAI HANISHA | D26: =IFERROR(__xludf.DUMMYFUNCTION("IMPORTRANGE(""https://docs.google.com/spreadsheets/d/1pcI0H5_o88uChaoz3Jx8Lo2Z71zohG9q1pYbJLiJRZI/edit?gid=760579392#gid=760579392"", address(row($Z26),column($Z26),,,""CSE-O""))"),251.0) -> 251 | E26: =ROUND(D26/$D$5*100,0) -> 60
A27: 22 | B27: 24981A05UE | C27: KORANANA MANIKANTA | D27: =IFERROR(__xludf.DUMMYFUNCTION("IMPORTRANGE(""https://docs.google.com/spreadsheets/d/1pcI0H5_o88uChaoz3Jx8Lo2Z71zohG9q1pYbJLiJRZI/edit?gid=760579392#gid=760579392"", address(row($Z27),column($Z27),,,""CSE-O""))"),148.0) -> 148 | E27: =ROUND(D27/$D$5*100,0) -> 35
A28: 23 | B28: 24981A05UF | C28: VEMULAMANDA SHANMUK SAI SANTHOSH VARMA | D28: =IFERROR(__xludf.DUMMYFUNCTION("IMPORTRANGE(""https://docs.google.com/spreadsheets/d/1pcI0H5_o88uChaoz3Jx8Lo2Z71zohG9q1pYbJLiJRZI/edit?gid=760579392#gid=760579392"", address(row($Z28),column($Z28),,,""CSE-O""))"),170.0) -> 170 | E28: =ROUND(D28/$D$5*100,0) -> 40
A29: 24 | B29: 24981A05UG | C29: KAMBAPU BHAVANI | D29: =IFERROR(__xludf.DUMMYFUNCTION("IMPORTRANGE(""https://docs.google.com/spreadsheets/d/1pcI0H5_o88uChaoz3Jx8Lo2Z71zohG9q1pYbJLiJRZI/edit?gid=760579392#gid=760579392"", address(row($Z29),column($Z29),,,""CSE-O""))"),328.0) -> 328 | E29: =ROUND(D29/$D$5*100,0) -> 78
A30: 25 | B30: 24981A05UH | C30: KANDIKATLA KEERTAN RAHUL SIDDU | D30: =IFERROR(__xludf.DUMMYFUNCTION("IMPORTRANGE(""https://docs.google.com/spreadsheets/d/1pcI0H5_o88uChaoz3Jx8Lo2Z71zohG9q1pYbJLiJRZI/edit?gid=760579392#gid=760579392"", address(row($Z30),column($Z30),,,""CSE-O""))"),105.0) -> 105 | E30: =ROUND(D30/$D$5*100,0) -> 25
A31: 26 | B31: 24981A05UI | C31: YELLETI JYOTHI | D31: =IFERROR(__xludf.DUMMYFUNCTION("IMPORTRANGE(""https://docs.google.com/spreadsheets/d/1pcI0H5_o88uChaoz3Jx8Lo2Z71zohG9q1pYbJLiJRZI/edit?gid=760579392#gid=760579392"", address(row($Z31),column($Z31),,,""CSE-O""))"),307.0) -> 307 | E31: =ROUND(D31/$D$5*100,0) -> 73
A32: 27 | B32: 24981A05UJ | C32: KARINKI DINESH | D32: =IFERROR(__xludf.DUMMYFUNCTION("IMPORTRANGE(""https://docs.google.com/spreadsheets/d/1pcI0H5_o88uChaoz3Jx8Lo2Z71zohG9q1pYbJLiJRZI/edit?gid=760579392#gid=760579392"", address(row($Z32),column($Z32),,,""CSE-O""))"),176.0) -> 176 | E32: =ROUND(D32/$D$5*100,0) -> 42
A33: 28 | B33: 24981A05UK | C33: KOLA NOMIKA | D33: =IFERROR(__xludf.DUMMYFUNCTION("IMPORTRANGE(""https://docs.google.com/spreadsheets/d/1pcI0H5_o88uChaoz3Jx8Lo2Z71zohG9q1pYbJLiJRZI/edit?gid=760579392#gid=760579392"", address(row($Z33),column($Z33),,,""CSE-O""))"),346.0) -> 346 | E33: =ROUND(D33/$D$5*100,0) -> 82
A34: 29 | B34: 24981A05UL | C34: KOMMOJU VYSHNAVI | D34: =IFERROR(__xludf.DUMMYFUNCTION("IMPORTRANGE(""https://docs.google.com/spreadsheets/d/1pcI0H5_o88uChaoz3Jx8Lo2Z71zohG9q1pYbJLiJRZI/edit?gid=760579392#gid=760579392"", address(row($Z34),column($Z34),,,""CSE-O""))"),326.0) -> 326 | E34: =ROUND(D34/$D$5*100,0) -> 77
A35: 30 | B35: 24981A05UM | C35: KONAKALLA HEMANTH BABU | D35: =IFERROR(__xludf.DUMMYFUNCTION("IMPORTRANGE(""https://docs.google.com/spreadsheets/d/1pcI0H5_o88uChaoz3Jx8Lo2Z71zohG9q1pYbJLiJRZI/edit?gid=760579392#gid=760579392"", address(row($Z35),column($Z35),,,""CSE-O""))"),226.0) -> 226 | E35: =ROUND(D35/$D$5*100,0) -> 54
A36: 31 | B36: 24981A05UN | C36: KORUPOLU CHANDRIKA | D36: =IFERROR(__xludf.DUMMYFUNCTION("IMPORTRANGE(""https://docs.google.com/spreadsheets/d/1pcI0H5_o88uChaoz3Jx8Lo2Z71zohG9q1pYbJLiJRZI/edit?gid=760579392#gid=760579392"", address(row($Z36),column($Z36),,,""CSE-O""))"),210.0) -> 210 | E36: =ROUND(D36/$D$5*100,0) -> 50
A37: 32 | B37: 24981A05UP | C37: KOTHURU SAI CHARAN | D37: =IFERROR(__xludf.DUMMYFUNCTION("IMPORTRANGE(""https://docs.google.com/spreadsheets/d/1pcI0H5_o88uChaoz3Jx8Lo2Z71zohG9q1pYbJLiJRZI/edit?gid=760579392#gid=760579392"", address(row($Z37),column($Z37),,,""CSE-O""))"),205.0) -> 205 | E37: =ROUND(D37/$D$5*100,0) -> 49
A38: 33 | B38: 24981A05UQ | C38: KOTTALA JAYANTHI | D38: =IFERROR(__xludf.DUMMYFUNCTION("IMPORTRANGE(""https://docs.google.com/spreadsheets/d/1pcI0H5_o88uChaoz3Jx8Lo2Z71zohG9q1pYbJLiJRZI/edit?gid=760579392#gid=760579392"", address(row($Z38),column($Z38),,,""CSE-O""))"),307.0) -> 307 | E38: =ROUND(D38/$D$5*100,0) -> 73
A39: 34 | B39: 24981A05UR | C39: LIMMI PRAVEEN BISAI | D39: =IFERROR(__xludf.DUMMYFUNCTION("IMPORTRANGE(""https://docs.google.com/spreadsheets/d/1pcI0H5_o88uChaoz3Jx8Lo2Z71zohG9q1pYbJLiJRZI/edit?gid=760579392#gid=760579392"", address(row($Z39),column($Z39),,,""CSE-O""))"),77.0) -> 77 | E39: =ROUND(D39/$D$5*100,0) -> 18
A40: 35 | B40: 24981A05US | C40: MOLLI CHANDRA KIRAN YADAV | D40: =IFERROR(__xludf.DUMMYFUNCTION("IMPORTRANGE(""https://docs.google.com/spreadsheets/d/1pcI0H5_o88uChaoz3Jx8Lo2Z71zohG9q1pYbJLiJRZI/edit?gid=760579392#gid=760579392"", address(row($Z40),column($Z40),,,""CSE-O""))"),262.0) -> 262 | E40: =ROUND(D40/$D$5*100,0) -> 62
...

Sheet CSE-P
A1: RAGHU ENGINEERING COLLEGE (A)
A2: Department of CSE
A3: 2025 AB CSE-P (REC) II B.Tech I Semester Attendance as on 11.06.2.205 onwards
A4: S.No | B4: Regd. No | C4: Name of the student | D4: Total | E4: Percentage
A5: Total classes taken till today | D5: =IFERROR(__xludf.DUMMYFUNCTION("IMPORTRANGE(""https://docs.google.com/spreadsheets/d/1pcI0H5_o88uChaoz3Jx8Lo2Z71zohG9q1pYbJLiJRZI/edit?gid=1794106843#gid=1794106843"", address(row($Z5),column($Z5),,,""CSE-P""))"),153.0) -> 153 | E5: %
A6: 1 | B6: 25985A0507 | C6: ANGULURI LAHARI | D6: =IFERROR(__xludf.DUMMYFUNCTION("IMPORTRANGE(""https://docs.google.com/spreadsheets/d/1pcI0H5_o88uChaoz3Jx8Lo2Z71zohG9q1pYbJLiJRZI/edit?gid=1794106843#gid=1794106843"", address(row($Z6),column($Z6),,,""CSE-P""))"),54.0) -> 54 | E6: =ROUND(D6/$D$5*100,0) -> 35
A7: 2 | B7: 25985A0508 | C7: AVANIGADDA VINAY | D7: =IFERROR(__xludf.DUMMYFUNCTION("IMPORTRANGE(""https://docs.google.com/spreadsheets/d/1pcI0H5_o88uChaoz3Jx8Lo2Z71zohG9q1pYbJLiJRZI/edit?gid=1794106843#gid=1794106843"", address(row($Z7),column($Z7),,,""CSE-P""))"),100.0) -> 100 | E7: =ROUND(D7/$D$5*100,0) -> 65
A8: 3 | B8: 25985A0509 | C8: BAIPOTHU GEYASRI | D8: =IFERROR(__xludf.DUMMYFUNCTION("IMPORTRANGE(""https://docs.google.com/spreadsheets/d/1pcI0H5_o88uChaoz3Jx8Lo2Z71zohG9q1pYbJLiJRZI/edit?gid=1794106843#gid=1794106843"", address(row($Z8),column($Z8),,,""CSE-P""))"),119.0) -> 119 | E8: =ROUND(D8/$D$5*100,0) -> 78
A9: 4 | B9: 25985A0510 | C9: BALI MAHESH BABU | D9: =IFERROR(__xludf.DUMMYFUNCTION("IMPORTRANGE(""https://docs.google.com/spreadsheets/d/1pcI0H5_o88uChaoz3Jx8Lo2Z71zohG9q1pYbJLiJRZI/edit?gid=1794106843#gid=1794106843"", address(row($Z9),column($Z9),,,""CSE-P""))"),122.0) -> 122 | E9: =ROUND(D9/$D$5*100,0) -> 80
A10: 5 | B10: 25985A0511 | C10: BALLA ANJI AKASH | D10: =IFERROR(__xludf.DUMMYFUNCTION("IMPORTRANGE(""https://docs.google.com/spreadsheets/d/1pcI0H5_o88uChaoz3Jx8Lo2Z71zohG9q1pYbJLiJRZI/edit?gid=1794106843#gid=1794106843"", address(row($Z10),column($Z10),,,""CSE-P""))"),43.0) -> 43 | E10: =ROUND(D10/$D$5*100,0) -> 28
A11: 6 | B11: 25985A0512 | C11: BANDELA GANESH | D11: =IFERROR(__xludf.DUMMYFUNCTION("IMPORTRANGE(""https://docs.google.com/spreadsheets/d/1pcI0H5_o88uChaoz3Jx8Lo2Z71zohG9q1pYbJLiJRZI/edit?gid=1794106843#gid=1794106843"", address(row($Z11),column($Z11),,,""CSE-P""))"),102.0) -> 102 | E11: =ROUND(D11/$D$5*100,0) -> 67
A12: 7 | B12: 25985A0513 | C12: BARNIKALA NITHIN | D12: =IFERROR(__xludf.DUMMYFUNCTION("IMPORTRANGE(""https://docs.google.com/spreadsheets/d/1pcI0H5_o88uChaoz3Jx8Lo2Z71zohG9q1pYbJLiJRZI/edit?gid=1794106843#gid=1794106843"", address(row($Z12),column($Z12),,,""CSE-P""))"),135.0) -> 135 | E12: =ROUND(D12/$D$5*100,0) -> 88
A13: 8 | B13: 25985A0514 | C13: BHIMAVARAPU GEETHU | D13: =IFERROR(__xludf.DUMMYFUNCTION("IMPORTRANGE(""https://docs.google.com/spreadsheets/d/1pcI0H5_o88uChaoz3Jx8Lo2Z71zohG9q1pYbJLiJRZI/edit?gid=1794106843#gid=1794106843"", address(row($Z13),column($Z13),,,""CSE-P""))"),132.0) -> 132 | E13: =ROUND(D13/$D$5*100,0) -> 86
A14: 9 | B14: 25985A0515 | C14: BODAPUDI DEVI PAVANI | D14: =IFERROR(__xludf.DUMMYFUNCTION("IMPORTRANGE(""https://docs.google.com/spreadsheets/d/1pcI0H5_o88uChaoz3Jx8Lo2Z71zohG9q1pYbJLiJRZI/edit?gid=1794106843#gid=1794106843"", address(row($Z14),column($Z14),,,""CSE-P""))"),140.0) -> 140 | E14: =ROUND(D14/$D$5*100,0) -> 92
A15: 10 | B15: 25985A0516 | C15: BODDU AKSHY KUMAR | D15: =IFERROR(__xludf.DUMMYFUNCTION("IMPORTRANGE(""https://docs.google.com/spreadsheets/d/1pcI0H5_o88uChaoz3Jx8Lo2Z71zohG9q1pYbJLiJRZI/edit?gid=1794106843#gid=1794106843"", address(row($Z15),column($Z15),,,""CSE-P""))"),65.0) -> 65 | E15: =ROUND(D15/$D$5*100,0) -> 42
A16: 11 | B16: 25985A0517 | C16: BOJJA MADHUSUDHAN RAO | D16: =IFERROR(__xludf.DUMMYFUNCTION("IMPORTRANGE(""https://docs.google.com/spreadsheets/d/1pcI0H5_o88uChaoz3Jx8Lo2Z71zohG9q1pYbJLiJRZI/edit?gid=1794106843#gid=1794106843"", address(row($Z16),column($Z16),,,""CSE-P""))"),133.0) -> 133 | E16: =ROUND(D16/$D$5*100,0) -> 87
A17: 12 | B17: 25985A0518 | C17: BOTCHU MOKSHA SAI | D17: =IFERROR(__xludf.DUMMYFUNCTION("IMPORTRANGE(""https://docs.google.com/spreadsheets/d/1pcI0H5_o88uChaoz3Jx8Lo2Z71zohG9q1pYbJLiJRZI/edit?gid=1794106843#gid=1794106843"", address(row($Z17),column($Z17),,,""CSE-P""))"),116.0) -> 116 | E17: =ROUND(D17/$D$5*100,0) -> 76
A18: 13 | B18: 25985A0519 | C18: BURAGAPU LASYA CHANDRIKA | D18: =IFERROR(__xludf.DUMMYFUNCTION("IMPORTRANGE(""https://docs.google.com/spreadsheets/d/1pcI0H5_o88uChaoz3Jx8Lo2Z71zohG9q1pYbJLiJRZI/edit?gid=1794106843#gid=1794106843"", address(row($Z18),column($Z18),,,""CSE-P""))"),123.0) -> 123 | E18: =ROUND(D18/$D$5*100,0) -> 80
A19: 14 | B19: 25985A0520 | C19: BUTHADA VINAY | D19: =IFERROR(__xludf.DUMMYFUNCTION("IMPORTRANGE(""https://docs.google.com/spreadsheets/d/1pcI0H5_o88uChaoz3Jx8Lo2Z71zohG9q1pYbJLiJRZI/edit?gid=1794106843#gid=1794106843"", address(row($Z19),column($Z19),,,""CSE-P""))"),11.0) -> 11 | E19: =ROUND(D19/$D$5*100,0) -> 7
A20: 15 | B20: 25985A0521 | C20: BYRISETTI KAMALESH | D20: =IFERROR(__xludf.DUMMYFUNCTION("IMPORTRANGE(""https://docs.google.com/spreadsheets/d/1pcI0H5_o88uChaoz3Jx8Lo2Z71zohG9q1pYbJLiJRZI/edit?gid=1794106843#gid=1794106843"", address(row($Z20),column($Z20),,,""CSE-P""))"),132.0) -> 132 | E20: =ROUND(D20/$D$5*100,0) -> 86
A21: 16 | B21: 25985A0522 | C21: CHATLA SNEHA | D21: =IFERROR(__xludf.DUMMYFUNCTION("IMPORTRANGE(""https://docs.google.com/spreadsheets/d/1pcI0H5_o88uChaoz3Jx8Lo2Z71zohG9q1pYbJLiJRZI/edit?gid=1794106843#gid=1794106843"", address(row($Z21),column($Z21),,,""CSE-P""))"),87.0) -> 87 | E21: =ROUND(D21/$D$5*100,0) -> 57
A22: 17 | B22: 25985A0523 | C22: CHEEKATLA UDAY SAI BHASKAR | D22: =IFERROR(__xludf.DUMMYFUNCTION("IMPORTRANGE(""https://docs.google.com/spreadsheets/d/1pcI0H5_o88uChaoz3Jx8Lo2Z71zohG9q1pYbJLiJRZI/edit?gid=1794106843#gid=1794106843"", address(row($Z22),column($Z22),,,""CSE-P""))"),7.0) -> 7 | E22: =ROUND(D22/$D$5*100,0) -> 5
A23: 18 | B23: 25985A0524 | C23: CHIKKALA ROHITH KUMAR | D23: =IFERROR(__xludf.DUMMYFUNCTION("IMPORTRANGE(""https://docs.google.com/spreadsheets/d/1pcI0H5_o88uChaoz3Jx8Lo2Z71zohG9q1pYbJLiJRZI/edit?gid=1794106843#gid=1794106843"", address(row($Z23),column($Z23),,,""CSE-P""))"),129.0) -> 129 | E23: =ROUND(D23/$D$5*100,0) -> 84
A24: 19 | B24: 25985A0525 | C24: CHILAKA SUVARNA KUMARI | D24: =IFERROR(__xludf.DUMMYFUNCTION("IMPORTRANGE(""https://docs.google.com/spreadsheets/d/1pcI0H5_o88uChaoz3Jx8Lo2Z71zohG9q1pYbJLiJRZI/edit?gid=1794106843#gid=1794106843"", address(row($Z24),column($Z24),,,""CSE-P""))"),114.0) -> 114 | E24: =ROUND(D24/$D$5*100,0) -> 75
A25: 20 | B25: 25985A0526 | C25: CHINTAPALLI SAI | D25: =IFERROR(__xludf.DUMMYFUNCTION("IMPORTRANGE(""https://docs.google.com/spreadsheets/d/1pcI0H5_o88uChaoz3Jx8Lo2Z71zohG9q1pYbJLiJRZI/edit?gid=1794106843#gid=1794106843"", address(row($Z25),column($Z25),,,""CSE-P""))"),132.0) -> 132 | E25: =ROUND(D25/$D$5*100,0) -> 86
A26: 21 | B26: 25985A0527 | C26: CHITTURI SAMUEL | D26: =IFERROR(__xludf.DUMMYFUNCTION("IMPORTRANGE(""https://docs.google.com/spreadsheets/d/1pcI0H5_o88uChaoz3Jx8Lo2Z71zohG9q1pYbJLiJRZI/edit?gid=1794106843#gid=1794106843"", address(row($Z26),column($Z26),,,""CSE-P""))"),108.0) -> 108 | E26: =ROUND(D26/$D$5*100,0) -> 71
A27: 22 | B27: 25985A0528 | C27: DANABALA SAILAJA | D27: =IFERROR(__xludf.DUMMYFUNCTION("IMPORTRANGE(""https://docs.google.com/spreadsheets/d/1pcI0H5_o88uChaoz3Jx8Lo2Z71zohG9q1pYbJLiJRZI/edit?gid=1794106843#gid=1794106843"", address(row($Z27),column($Z27),,,""CSE-P""))"),137.0) -> 137 | E27: =ROUND(D27/$D$5*100,0) -> 90
A28: 23 | B28: 25985A0529 | C28: DEVAGANUGULA N V D S S KOTESH | D28: =IFERROR(__xludf.DUMMYFUNCTION("IMPORTRANGE(""https://docs.google.com/spreadsheets/d/1pcI0H5_o88uChaoz3Jx8Lo2Z71zohG9q1pYbJLiJRZI/edit?gid=1794106843#gid=1794106843"", address(row($Z28),column($Z28),,,""CSE-P""))"),119.0) -> 119 | E28: =ROUND(D28/$D$5*100,0) -> 78
A29: 24 | B29: 25985A0530 | C29: DINESH KUMAR CHIDARABOYINA | D29: =IFERROR(__xludf.DUMMYFUNCTION("IMPORTRANGE(""https://docs.google.com/spreadsheets/d/1pcI0H5_o88uChaoz3Jx8Lo2Z71zohG9q1pYbJLiJRZI/edit?gid=1794106843#gid=1794106843"", address(row($Z29),column($Z29),,,""CSE-P""))"),146.0) -> 146 | E29: =ROUND(D29/$D$5*100,0) -> 95
A30: 25 | B30: 25985A0531 | C30: DOPPALAPUDI HEMANTH | D30: =IFERROR(__xludf.DUMMYFUNCTION("IMPORTRANGE(""https://docs.google.com/spreadsheets/d/1pcI0H5_o88uChaoz3Jx8Lo2Z71zohG9q1pYbJLiJRZI/edit?gid=1794106843#gid=1794106843"", address(row($Z30),column($Z30),,,""CSE-P""))"),108.0) -> 108 | E30: =ROUND(D30/$D$5*100,0) -> 71
A31: 26 | B31: 25985A0532 | C31: DUVVARAPU YASWANTH | D31: =IFERROR(__xludf.DUMMYFUNCTION("IMPORTRANGE(""https://docs.google.com/spreadsheets/d/1pcI0H5_o88uChaoz3Jx8Lo2Z71zohG9q1pYbJLiJRZI/edit?gid=1794106843#gid=1794106843"", address(row($Z31),column($Z31),,,""CSE-P""))"),124.0) -> 124 | E31: =ROUND(D31/$D$5*100,0) -> 81
A32: 27 | B32: 25985A0533 | C32: ELAPANDA PURNIMA | D32: =IFERROR(__xludf.DUMMYFUNCTION("IMPORTRANGE(""https://docs.google.com/spreadsheets/d/1pcI0H5_o88uChaoz3Jx8Lo2Z71zohG9q1pYbJLiJRZI/edit?gid=1794106843#gid=1794106843"", address(row($Z32),column($Z32),,,""CSE-P""))"),126.0) -> 126 | E32: =ROUND(D32/$D$5*100,0) -> 82
A33: 28 | B33: 25985A0534 | C33: GEDDAM SANJAY KUMAR | D33: =IFERROR(__xludf.DUMMYFUNCTION("IMPORTRANGE(""https://docs.google.com/spreadsheets/d/1pcI0H5_o88uChaoz3Jx8Lo2Z71zohG9q1pYbJLiJRZI/edit?gid=1794106843#gid=1794106843"", address(row($Z33),column($Z33),,,""CSE-P""))"),111.0) -> 111 | E33: =ROUND(D33/$D$5*100,0) -> 73
A34: 29 | B34: 25985A0535 | C34: GOPASANA ANUSH KUMAR | D34: =IFERROR(__xludf.DUMMYFUNCTION("IMPORTRANGE(""https://docs.google.com/spreadsheets/d/1pcI0H5_o88uChaoz3Jx8Lo2Z71zohG9q1pYbJLiJRZI/edit?gid=1794106843#gid=1794106843"", address(row($Z34),column($Z34),,,""CSE-P""))"),88.0) -> 88 | E34: =ROUND(D34/$D$5*100,0) -> 58
A35: 30 | B35: 25985A0536 | C35: GOTTAPU BHANU PRAKASH | D35: =IFERROR(__xludf.DUMMYFUNCTION("IMPORTRANGE(""https://docs.google.com/spreadsheets/d/1pcI0H5_o88uChaoz3Jx8Lo2Z71zohG9q1pYbJLiJRZI/edit?gid=1794106843#gid=1794106843"", address(row($Z35),column($Z35),,,""CSE-P""))"),111.0) -> 111 | E35: =ROUND(D35/$D$5*100,0) -> 73
A36: 31 | B36: 25985A0537 | C36: GUDURI KUMARA VEERA VENKATA SUBRAHMANYAM | D36: =IFERROR(__xludf.DUMMYFUNCTION("IMPORTRANGE(""https://docs.google.com/spreadsheets/d/1pcI0H5_o88uChaoz3Jx8Lo2Z71zohG9q1pYbJLiJRZI/edit?gid=1794106843#gid=1794106843"", address(row($Z36),column($Z36),,,""CSE-P""))"),113.0) -> 113 | E36: =ROUND(D36/$D$5*100,0) -> 74
A37: 32 | B37: 25985A0538 | C37: GUNTUR PAVAN | D37: =IFERROR(__xludf.DUMMYFUNCTION("IMPORTRANGE(""https://docs.google.com/spreadsheets/d/1pcI0H5_o88uChaoz3Jx8Lo2Z71zohG9q1pYbJLiJRZI/edit?gid=1794106843#gid=1794106843"", address(row($Z37),column($Z37),,,""CSE-P""))"),95.0) -> 95 | E37: =ROUND(D37/$D$5*100,0) -> 62
A38: 33 | B38: 25985A0539 | C38: GURAJAPU THARUN | D38: =IFERROR(__xludf.DUMMYFUNCTION("IMPORTRANGE(""https://docs.google.com/spreadsheets/d/1pcI0H5_o88uChaoz3Jx8Lo2Z71zohG9q1pYbJLiJRZI/edit?gid=1794106843#gid=1794106843"", address(row($Z38),column($Z38),,,""CSE-P""))"),119.0) -> 119 | E38: =ROUND(D38/$D$5*100,0) -> 78
A39: 34 | B39: 25985A0540 | C39: GURANA SWAPNA | D39: =IFERROR(__xludf.DUMMYFUNCTION("IMPORTRANGE(""https://docs.google.com/spreadsheets/d/1pcI0H5_o88uChaoz3Jx8Lo2Z71zohG9q1pYbJLiJRZI/edit?gid=1794106843#gid=1794106843"", address(row($Z39),column($Z39),,,""CSE-P""))"),140.0) -> 140 | E39: =ROUND(D39/$D$5*100,0) -> 92
A40: 35 | B40: 25985A0541 | C40: ILAPARTHI ISSAKU | D40: =IFERROR(__xludf.DUMMYFUNCTION("IMPORTRANGE(""https://docs.google.com/spreadsheets/d/1pcI0H5_o88uChaoz3Jx8Lo2Z71zohG9q1pYbJLiJRZI/edit?gid=1794106843#gid=1794106843"", address(row($Z40),column($Z40),,,""CSE-P""))"),107.0) -> 107 | E40: =ROUND(D40/$D$5*100,0) -> 70
...

Sheet CSE-Q
A1: RAGHU ENGINEERING COLLEGE (A)
A2: Department of CSE
A3: 2025 AB CSE-Q (REC) II B.Tech I Semester Attendance as on 11.06.2.205 onwards
A4: S.No | B4: Regd. No | C4: Name of the student | D4: Total | E4: Percentage
A5: Total classes taken till today | D5: =IFERROR(__xludf.DUMMYFUNCTION("IMPORTRANGE(""https://docs.google.com/spreadsheets/d/1pcI0H5_o88uChaoz3Jx8Lo2Z71zohG9q1pYbJLiJRZI/edit?gid=1349297439#gid=1349297439"", address(row($Z5),column($Z5),,,""CSE-Q""))"),162.0) -> 162 | E5: %
A6: 1 | B6: 25985A0582 | C6: NALLA VINAY KUMAR | D6: =IFERROR(__xludf.DUMMYFUNCTION("IMPORTRANGE(""https://docs.google.com/spreadsheets/d/1pcI0H5_o88uChaoz3Jx8Lo2Z71zohG9q1pYbJLiJRZI/edit?gid=1349297439#gid=1349297439"", address(row($Z6),column($Z6),,,""CSE-Q""))"),63.0) -> 63 | E6: =ROUND(D6/$D$5*100,0) -> 39
A7: 2 | B7: 25985A0583 | C7: NARAVA SRI HARI KARTHIK | D7: =IFERROR(__xludf.DUMMYFUNCTION("IMPORTRANGE(""https://docs.google.com/spreadsheets/d/1pcI0H5_o88uChaoz3Jx8Lo2Z71zohG9q1pYbJLiJRZI/edit?gid=1349297439#gid=1349297439"", address(row($Z7),column($Z7),,,""CSE-Q""))"),79.0) -> 79 | E7: =ROUND(D7/$D$5*100,0) -> 49
A8: 3 | B8: 25985A0584 | C8: NERALLA DILLESWARA RAO | D8: =IFERROR(__xludf.DUMMYFUNCTION("IMPORTRANGE(""https://docs.google.com/spreadsheets/d/1pcI0H5_o88uChaoz3Jx8Lo2Z71zohG9q1pYbJLiJRZI/edit?gid=1349297439#gid=1349297439"", address(row($Z8),column($Z8),,,""CSE-Q""))"),116.0) -> 116 | E8: =ROUND(D8/$D$5*100,0) -> 72
A9: 4 | B9: 25985A0585 | C9: PAIDI SIVA PRASAD | D9: =IFERROR(__xludf.DUMMYFUNCTION("IMPORTRANGE(""https://docs.google.com/spreadsheets/d/1pcI0H5_o88uChaoz3Jx8Lo2Z71zohG9q1pYbJLiJRZI/edit?gid=1349297439#gid=1349297439"", address(row($Z9),column($Z9),,,""CSE-Q""))"),113.0) -> 113 | E9: =ROUND(D9/$D$5*100,0) -> 70
A10: 5 | B10: 25985A0586 | C10: PAILA VYKUNTA RAO | D10: =IFERROR(__xludf.DUMMYFUNCTION("IMPORTRANGE(""https://docs.google.com/spreadsheets/d/1pcI0H5_o88uChaoz3Jx8Lo2Z71zohG9q1pYbJLiJRZI/edit?gid=1349297439#gid=1349297439"", address(row($Z10),column($Z10),,,""CSE-Q""))"),106.0) -> 106 | E10: =ROUND(D10/$D$5*100,0) -> 65
A11: 6 | B11: 25985A0587 | C11: PALLA SIVA SHANKAR | D11: =IFERROR(__xludf.DUMMYFUNCTION("IMPORTRANGE(""https://docs.google.com/spreadsheets/d/1pcI0H5_o88uChaoz3Jx8Lo2Z71zohG9q1pYbJLiJRZI/edit?gid=1349297439#gid=1349297439"", address(row($Z11),column($Z11),,,""CSE-Q""))"),116.0) -> 116 | E11: =ROUND(D11/$D$5*100,0) -> 72
A12: 7 | B12: 25985A0588 | C12: PALLA SUBHASH | D12: =IFERROR(__xludf.DUMMYFUNCTION("IMPORTRANGE(""https://docs.google.com/spreadsheets/d/1pcI0H5_o88uChaoz3Jx8Lo2Z71zohG9q1pYbJLiJRZI/edit?gid=1349297439#gid=1349297439"", address(row($Z12),column($Z12),,,""CSE-Q""))"),102.0) -> 102 | E12: =ROUND(D12/$D$5*100,0) -> 63
A13: 8 | B13: 25985A0589 | C13: PATARLAPALLI SRAVANTHI | D13: =IFERROR(__xludf.DUMMYFUNCTION("IMPORTRANGE(""https://docs.google.com/spreadsheets/d/1pcI0H5_o88uChaoz3Jx8Lo2Z71zohG9q1pYbJLiJRZI/edit?gid=1349297439#gid=1349297439"", address(row($Z13),column($Z13),,,""CSE-Q""))"),154.0) -> 154 | E13: =ROUND(D13/$D$5*100,0) -> 95
A14: 9 | B14: 25985A0590 | C14: PATHALA VENU | D14: =IFERROR(__xludf.DUMMYFUNCTION("IMPORTRANGE(""https://docs.google.com/spreadsheets/d/1pcI0H5_o88uChaoz3Jx8Lo2Z71zohG9q1pYbJLiJRZI/edit?gid=1349297439#gid=1349297439"", address(row($Z14),column($Z14),,,""CSE-Q""))"),128.0) -> 128 | E14: =ROUND(D14/$D$5*100,0) -> 79
A15: 10 | B15: 25985A0591 | C15: PENKI PARDHA SARADHI | D15: =IFERROR(__xludf.DUMMYFUNCTION("IMPORTRANGE(""https://docs.google.com/spreadsheets/d/1pcI0H5_o88uChaoz3Jx8Lo2Z71zohG9q1pYbJLiJRZI/edit?gid=1349297439#gid=1349297439"", address(row($Z15),column($Z15),,,""CSE-Q""))"),126.0) -> 126 | E15: =ROUND(D15/$D$5*100,0) -> 78
A16: 11 | B16: 25985A0592 | C16: PENUGURTHY PURNIMA | D16: =IFERROR(__xludf.DUMMYFUNCTION("IMPORTRANGE(""https://docs.google.com/spreadsheets/d/1pcI0H5_o88uChaoz3Jx8Lo2Z71zohG9q1pYbJLiJRZI/edit?gid=1349297439#gid=1349297439"", address(row($Z16),column($Z16),,,""CSE-Q""))"),114.0) -> 114 | E16: =ROUND(D16/$D$5*100,0) -> 70
A17: 12 | B17: 25985A0593 | C17: PINABOINA JAYA SURYA | D17: =IFERROR(__xludf.DUMMYFUNCTION("IMPORTRANGE(""https://docs.google.com/spreadsheets/d/1pcI0H5_o88uChaoz3Jx8Lo2Z71zohG9q1pYbJLiJRZI/edit?gid=1349297439#gid=1349297439"", address(row($Z17),column($Z17),,,""CSE-Q""))"),81.0) -> 81 | E17: =ROUND(D17/$D$5*100,0) -> 50
A18: 13 | B18: 25985A0594 | C18: PINDI PYDI VENKATA GANESH | D18: =IFERROR(__xludf.DUMMYFUNCTION("IMPORTRANGE(""https://docs.google.com/spreadsheets/d/1pcI0H5_o88uChaoz3Jx8Lo2Z71zohG9q1pYbJLiJRZI/edit?gid=1349297439#gid=1349297439"", address(row($Z18),column($Z18),,,""CSE-Q""))"),118.0) -> 118 | E18: =ROUND(D18/$D$5*100,0) -> 73
A19: 14 | B19: 25985A0595 | C19: POOLAGONI MANASA | D19: =IFERROR(__xludf.DUMMYFUNCTION("IMPORTRANGE(""https://docs.google.com/spreadsheets/d/1pcI0H5_o88uChaoz3Jx8Lo2Z71zohG9q1pYbJLiJRZI/edit?gid=1349297439#gid=1349297439"", address(row($Z19),column($Z19),,,""CSE-Q""))"),97.0) -> 97 | E19: =ROUND(D19/$D$5*100,0) -> 60
A20: 15 | B20: 25985A0596 | C20: POTHALA SRI RATNA | D20: =IFERROR(__xludf.DUMMYFUNCTION("IMPORTRANGE(""https://docs.google.com/spreadsheets/d/1pcI0H5_o88uChaoz3Jx8Lo2Z71zohG9q1pYbJLiJRZI/edit?gid=1349297439#gid=1349297439"", address(row($Z20),column($Z20),,,""CSE-Q""))"),140.0) -> 140 | E20: =ROUND(D20/$D$5*100,0) -> 86
A21: 16 | B21: 25985A0597 | C21: POTHU SRINIVASA RAO | D21: =IFERROR(__xludf.DUMMYFUNCTION("IMPORTRANGE(""https://docs.google.com/spreadsheets/d/1pcI0H5_o88uChaoz3Jx8Lo2Z71zohG9q1pYbJLiJRZI/edit?gid=1349297439#gid=1349297439"", address(row($Z21),column($Z21),,,""CSE-Q""))"),114.0) -> 114 | E21: =ROUND(D21/$D$5*100,0) -> 70
A22: 17 | B22: 25985A0598 | C22: PRASADULA VINAY KUMAR | D22: =IFERROR(__xludf.DUMMYFUNCTION("IMPORTRANGE(""https://docs.google.com/spreadsheets/d/1pcI0H5_o88uChaoz3Jx8Lo2Z71zohG9q1pYbJLiJRZI/edit?gid=1349297439#gid=1349297439"", address(row($Z22),column($Z22),,,""CSE-Q""))"),79.0) -> 79 | E22: =ROUND(D22/$D$5*100,0) -> 49
A23: 18 | B23: 25985A0599 | C23: PULIVARTHI VENKATESH | D23: =IFERROR(__xludf.DUMMYFUNCTION("IMPORTRANGE(""https://docs.google.com/spreadsheets/d/1pcI0H5_o88uChaoz3Jx8Lo2Z71zohG9q1pYbJLiJRZI/edit?gid=1349297439#gid=1349297439"", address(row($Z23),column($Z23),,,""CSE-Q""))"),111.0) -> 111 | E23: =ROUND(D23/$D$5*100,0) -> 69
A24: 19 | B24: 25985A05A0 | C24: PYDADA SAILU | D24: =IFERROR(__xludf.DUMMYFUNCTION("IMPORTRANGE(""https://docs.google.com/spreadsheets/d/1pcI0H5_o88uChaoz3Jx8Lo2Z71zohG9q1pYbJLiJRZI/edit?gid=1349297439#gid=1349297439"", address(row($Z24),column($Z24),,,""CSE-Q""))"),154.0) -> 154 | E24: =ROUND(D24/$D$5*100,0) -> 95
A25: 20 | B25: 25985A05A1 | C25: RAJETI SHINY | D25: =IFERROR(__xludf.DUMMYFUNCTION("IMPORTRANGE(""https://docs.google.com/spreadsheets/d/1pcI0H5_o88uChaoz3Jx8Lo2Z71zohG9q1pYbJLiJRZI/edit?gid=1349297439#gid=1349297439"", address(row($Z25),column($Z25),,,""CSE-Q""))"),133.0) -> 133 | E25: =ROUND(D25/$D$5*100,0) -> 82
A26: 21 | B26: 25985A05A2 | C26: RASAMSETTI YUVA SATYA PRASANNA | D26: =IFERROR(__xludf.DUMMYFUNCTION("IMPORTRANGE(""https://docs.google.com/spreadsheets/d/1pcI0H5_o88uChaoz3Jx8Lo2Z71zohG9q1pYbJLiJRZI/edit?gid=1349297439#gid=1349297439"", address(row($Z26),column($Z26),,,""CSE-Q""))"),137.0) -> 137 | E26: =ROUND(D26/$D$5*100,0) -> 85
A27: 22 | B27: 25985A05A3 | C27: RAYAPUDI SUMANTH | D27: =IFERROR(__xludf.DUMMYFUNCTION("IMPORTRANGE(""https://docs.google.com/spreadsheets/d/1pcI0H5_o88uChaoz3Jx8Lo2Z71zohG9q1pYbJLiJRZI/edit?gid=1349297439#gid=1349297439"", address(row($Z27),column($Z27),,,""CSE-Q""))"),95.0) -> 95 | E27: =ROUND(D27/$D$5*100,0) -> 59
A28: 23 | B28: 25985A05A4 | C28: RAYI MANI KANTA | D28: =IFERROR(__xludf.DUMMYFUNCTION("IMPORTRANGE(""https://docs.google.com/spreadsheets/d/1pcI0H5_o88uChaoz3Jx8Lo2Z71zohG9q1pYbJLiJRZI/edit?gid=1349297439#gid=1349297439"", address(row($Z28),column($Z28),,,""CSE-Q""))"),118.0) -> 118 | E28: =ROUND(D28/$D$5*100,0) -> 73
A29: 24 | B29: 25985A05A5 | C29: SALUGULA BHANU SRI | D29: =IFERROR(__xludf.DUMMYFUNCTION("IMPORTRANGE(""https://docs.google.com/spreadsheets/d/1pcI0H5_o88uChaoz3Jx8Lo2Z71zohG9q1pYbJLiJRZI/edit?gid=1349297439#gid=1349297439"", address(row($Z29),column($Z29),,,""CSE-Q""))"),129.0) -> 129 | E29: =ROUND(D29/$D$5*100,0) -> 80
A30: 25 | B30: 25985A05A6 | C30: SAMBANGI SRAVANI | D30: =IFERROR(__xludf.DUMMYFUNCTION("IMPORTRANGE(""https://docs.google.com/spreadsheets/d/1pcI0H5_o88uChaoz3Jx8Lo2Z71zohG9q1pYbJLiJRZI/edit?gid=1349297439#gid=1349297439"", address(row($Z30),column($Z30),,,""CSE-Q""))"),110.0) -> 110 | E30: =ROUND(D30/$D$5*100,0) -> 68
A31: 26 | B31: 25985A05A7 | C31: SANTHA NAGA CHARAN TEJA | D31: =IFERROR(__xludf.DUMMYFUNCTION("IMPORTRANGE(""https://docs.google.com/spreadsheets/d/1pcI0H5_o88uChaoz3Jx8Lo2Z71zohG9q1pYbJLiJRZI/edit?gid=1349297439#gid=1349297439"", address(row($Z31),column($Z31),,,""CSE-Q""))"),103.0) -> 103 | E31: =ROUND(D31/$D$5*100,0) -> 64
A32: 27 | B32: 25985A05A8 | C32: SARAGADAM VENKATA GANESH | D32: =IFERROR(__xludf.DUMMYFUNCTION("IMPORTRANGE(""https://docs.google.com/spreadsheets/d/1pcI0H5_o88uChaoz3Jx8Lo2Z71zohG9q1pYbJLiJRZI/edit?gid=1349297439#gid=1349297439"", address(row($Z32),column($Z32),,,""CSE-Q""))"),121.0) -> 121 | E32: =ROUND(D32/$D$5*100,0) -> 75
A33: 28 | B33: 25985A05A9 | C33: SETTYPALLI KARTHIK | D33: =IFERROR(__xludf.DUMMYFUNCTION("IMPORTRANGE(""https://docs.google.com/spreadsheets/d/1pcI0H5_o88uChaoz3Jx8Lo2Z71zohG9q1pYbJLiJRZI/edit?gid=1349297439#gid=1349297439"", address(row($Z33),column($Z33),,,""CSE-Q""))"),140.0) -> 140 | E33: =ROUND(D33/$D$5*100,0) -> 86
A34: 29 | B34: 25985A05B0 | C34: SHAIK AHMAD MOHIDDIN | D34: =IFERROR(__xludf.DUMMYFUNCTION("IMPORTRANGE(""https://docs.google.com/spreadsheets/d/1pcI0H5_o88uChaoz3Jx8Lo2Z71zohG9q1pYbJLiJRZI/edit?gid=1349297439#gid=1349297439"", address(row($Z34),column($Z34),,,""CSE-Q""))"),130.0) -> 130 | E34: =ROUND(D34/$D$5*100,0) -> 80
A35: 30 | B35: 25985A05B1 | C35: SHAIK JOHNVALI | D35: =IFERROR(__xludf.DUMMYFUNCTION("IMPORTRANGE(""https://docs.google.com/spreadsheets/d/1pcI0H5_o88uChaoz3Jx8Lo2Z71zohG9q1pYbJLiJRZI/edit?gid=1349297439#gid=1349297439"", address(row($Z35),column($Z35),,,""CSE-Q""))"),98.0) -> 98 | E35: =ROUND(D35/$D$5*100,0) -> 60
A36: 31 | B36: 25985A05B2 | C36: SHAIK RAHEEM | D36: =IFERROR(__xludf.DUMMYFUNCTION("IMPORTRANGE(""https://docs.google.com/spreadsheets/d/1pcI0H5_o88uChaoz3Jx8Lo2Z71zohG9q1pYbJLiJRZI/edit?gid=1349297439#gid=1349297439"", address(row($Z36),column($Z36),,,""CSE-Q""))"),140.0) -> 140 | E36: =ROUND(D36/$D$5*100,0) -> 86
A37: 32 | B37: 25985A05B3 | C37: SHAIK SAMEERA | D37: =IFERROR(__xludf.DUMMYFUNCTION("IMPORTRANGE(""https://docs.google.com/spreadsheets/d/1pcI0H5_o88uChaoz3Jx8Lo2Z71zohG9q1pYbJLiJRZI/edit?gid=1349297439#gid=1349297439"", address(row($Z37),column($Z37),,,""CSE-Q""))"),94.0) -> 94 | E37: =ROUND(D37/$D$5*100,0) -> 58
A38: 33 | B38: 25985A05B4 | C38: SHAIK YASIN | D38: =IFERROR(__xludf.DUMMYFUNCTION("IMPORTRANGE(""https://docs.google.com/spreadsheets/d/1pcI0H5_o88uChaoz3Jx8Lo2Z71zohG9q1pYbJLiJRZI/edit?gid=1349297439#gid=1349297439"", address(row($Z38),column($Z38),,,""CSE-Q""))"),130.0) -> 130 | E38: =ROUND(D38/$D$5*100,0) -> 80
A39: 34 | B39: 25985A05B5 | C39: SHEK BASHEER | D39: =IFERROR(__xludf.DUMMYFUNCTION("IMPORTRANGE(""https://docs.google.com/spreadsheets/d/1pcI0H5_o88uChaoz3Jx8Lo2Z71zohG9q1pYbJLiJRZI/edit?gid=1349297439#gid=1349297439"", address(row($Z39),column($Z39),,,""CSE-Q""))"),138.0) -> 138 | E39: =ROUND(D39/$D$5*100,0) -> 85
A40: 35 | B40: 25985A05B6 | C40: SONTYANA SELINA | D40: =IFERROR(__xludf.DUMMYFUNCTION("IMPORTRANGE(""https://docs.google.com/spreadsheets/d/1pcI0H5_o88uChaoz3Jx8Lo2Z71zohG9q1pYbJLiJRZI/edit?gid=1349297439#gid=1349297439"", address(row($Z40),column($Z40),,,""CSE-Q""))"),127.0) -> 127 | E40: =ROUND(D40/$D$5*100,0) -> 78
...

Sheet Consolidated
B4: CSE-M | C4: CSE-N | D4: CSE-O | E4: CSE-P | F4: CSE-Q | G4: Total
A5: >75 | B5: ='CSE-M'!C81 -> 29 | C5: ='CSE-N'!C80 -> 29 | D5: ='CSE-O'!C79 -> 23 | E5: ='CSE-P'!C83 -> 37 | F5: ='CSE-Q'!C82 -> 28 | G5: =SUM(B5:F5) -> 146
A6: >65 AND <74 | B6: ='CSE-M'!C82 -> 21 | C6: ='CSE-N'!C81 -> 14 | D6: ='CSE-O'!C80 -> 16 | E6: ='CSE-P'!C84 -> 25 | F6: ='CSE-Q'!C83 -> 18 | G6: =SUM(B6:F6) -> 94
A7: >50 AND <64 | B7: ='CSE-M'!C83 -> 21 | C7: ='CSE-N'!C82 -> 20 | D7: ='CSE-O'!C81 -> 10 | E7: ='CSE-P'!C85 -> 4 | F7: ='CSE-Q'!C84 -> 17 | G7: =SUM(B7:F7) -> 72
A8: >25 AND <49 | B8: ='CSE-M'!C84 -> 2 | C8: ='CSE-N'!C83 -> 8 | D8: ='CSE-O'!C82 -> 18 | E8: ='CSE-P'!C86 -> 4 | F8: ='CSE-Q'!C85 -> 10 | G8: =SUM(B8:F8) -> 42
A9: >1 AND <24 | B9: ='CSE-M'!C85 -> 0 | C9: ='CSE-N'!C84 -> 1 | D9: ='CSE-O'!C83 -> 1 | E9: ='CSE-P'!C87 -> 5 | F9: ='CSE-Q'!C86 -> 1 | G9: =SUM(B9:F9) -> 8
